orderBookInput.txt
ABB|A|S|343453|5800|21.1300
ABB|D|343453
IBM|A|B|123450|1000|100.0000
IBM|A|S|123451|1000|100.0000
MSFT|A|B|123452|2000|70.0000
MSFT|A|B|123453|3000|70.0000
MSFT|A|S|123454|4000|71.0000
MS|A|B|123455|2000|50.0000
MS|A|B|123456|3000|50.0000
MS|A|S|123457|4000|51.0000
MS|D|123455
MS|D|123456
MS|D|123457
IBM|M|123450|500|100.0000
MSFT|M|123453|8000|70.0000
