orderBookOutput.txt
Printing individual symbol:
IBM|B|100.0000|500|1
IBM|S|100.0000|1000|1
MSFT|B|70.0000|10000|2
MSFT|S|71.0000|4000|1

Printing the entire book:
IBM|B|100.0000|500|1
IBM|S|100.0000|1000|1
MSFT|B|70.0000|10000|2
MSFT|S|71.0000|4000|1
